I'm sorry, but an uncaught exception occurred.

While running game code:
  File "game/script.rpy", line 21594, in script call
    call script2 from _call_script2
  File "game/script2.rpy", line 19463, in script call
    call script3 from _call_script3
  File "game/script.rpy", line 21594, in script call
    call script2 from _call_script2
  File "game/script2.rpy", line 19463, in script call
    call script3 from _call_script3
ScriptError: could not find label 'script3'.

-- Full Traceback ------------------------------------------------------------

Full traceback:
  File "game/script.rpy", line 21594, in script call
    call script2 from _call_script2
  File "game/script2.rpy", line 19463, in script call
    call script3 from _call_script3
  File "C:\Users\Aris\Documents\renpy-8.3.7-sdk\renpy\ast.py", line 1427, in execute
    rv = renpy.game.context().call(label, return_site=self.next.name)
  File "game/script.rpy", line 21594, in script call
    call script2 from _call_script2
  File "game/script2.rpy", line 19463, in script call
    call script3 from _call_script3
  File "C:\Users\Aris\Documents\renpy-8.3.7-sdk\renpy\script.py", line 1103, in lookup
    raise ScriptError("could not find label '%s'." % str(original))
ScriptError: could not find label 'script3'.

Windows-10-10.0.26100 AMD64
Ren'Py 8.3.7.25031702
Arisization Project Version_0.0.5
Thu Sep 18 19:44:48 2025
